{
  "comments": [
    {
      "key": {
        "uuid": "e097b326_c74cba2f",
        "filename": "utils/vtest_py/tests/test_cem_7113.py",
        "patchSetId": 1
      },
      "lineNbr": 9,
      "author": {
        "id": 631
      },
      "writtenOn": "2019-09-23T07:42:26Z",
      "side": 1,
      "message": "For me it was cribbing that vtconst couldn\u0027t be found. The reason being it is under /lib\nand we have not appended the /lib path in sys.path. \nAfter I added this line \nsys.path.append(os.getcwd() + \u0027/lib/\u0027)\nit started worked.\nWondering why it didn\u0027t crib for you.\nCan you please check?\n\nSame for the other fabric test case file.",
      "range": {
        "startLine": 8,
        "startChar": 0,
        "endLine": 9,
        "endChar": 23
      },
      "revId": "aa14a447e97dbe4aaeb31e7af7e5130cec50c9d8",
      "serverId": "c72cd27d-1743-4a55-84a4-cd13b8400c52",
      "unresolved": true
    },
    {
      "key": {
        "uuid": "a8146a52_88a3d1bf",
        "filename": "utils/vtest_py/tests/test_cem_7113.py",
        "patchSetId": 1
      },
      "lineNbr": 9,
      "author": {
        "id": 232
      },
      "writtenOn": "2019-09-23T07:57:34Z",
      "side": 1,
      "message": "Should the review be marked as failed with non-voting if this UT failed?",
      "parentUuid": "e097b326_c74cba2f",
      "range": {
        "startLine": 8,
        "startChar": 0,
        "endLine": 9,
        "endChar": 23
      },
      "revId": "aa14a447e97dbe4aaeb31e7af7e5130cec50c9d8",
      "serverId": "c72cd27d-1743-4a55-84a4-cd13b8400c52",
      "unresolved": true
    },
    {
      "key": {
        "uuid": "dff5e52a_158860ed",
        "filename": "utils/vtest_py/tests/test_cem_7113.py",
        "patchSetId": 1
      },
      "lineNbr": 9,
      "author": {
        "id": 643
      },
      "writtenOn": "2019-09-23T11:02:02Z",
      "side": 1,
      "message": "I run it locally, its passing without any issue. Not sure, if you run this particular test alone, it will throw error with \"vtconst file not found\".\nI think, pytest does some optimisation and resolve file paths internally, so it\u0027s passing.\nAnyhow, I will add the line \"sys.path.append(os.getcwd() + \u0027/lib/\u0027)\" to all test cases.",
      "parentUuid": "a8146a52_88a3d1bf",
      "range": {
        "startLine": 8,
        "startChar": 0,
        "endLine": 9,
        "endChar": 23
      },
      "revId": "aa14a447e97dbe4aaeb31e7af7e5130cec50c9d8",
      "serverId": "c72cd27d-1743-4a55-84a4-cd13b8400c52",
      "unresolved": true
    }
  ]
}